[2022-08-25 06:56:45] INFO Watching for file changes with StatReloader
[2022-08-25 06:56:47] ERROR Internal Server Error: /users/login
Traceback (most recent call last):
  File "C:\Python311\Lib\site-packages\django\core\handlers\exception.py", line 55, in inner
    response = get_response(request)
               ^^^^^^^^^^^^^^^^^^^^^
  File "C:\Python311\Lib\site-packages\django\core\handlers\base.py", line 197, in _get_response
    response = wrapped_callback(request, *callback_args, **callback_kwargs)
               ^^^^^^^^^^^^^^^^^^^^^^^^^^^^^^^^^^^^^^^^^^^^^^^^^^^^^^^^^^^^
  File "C:\Python311\Lib\site-packages\django\views\decorators\csrf.py", line 54, in wrapped_view
    return view_func(*args, **kwargs)
           ^^^^^^^^^^^^^^^^^^^^^^^^^^
  File "C:\Python311\Lib\site-packages\django\views\generic\base.py", line 103, in view
    return self.dispatch(request, *args, **kwargs)
           ^^^^^^^^^^^^^^^^^^^^^^^^^^^^^^^^^^^^^^^
  File "C:\Python311\Lib\site-packages\rest_framework\views.py", line 509, in dispatch
    response = self.handle_exception(exc)
               ^^^^^^^^^^^^^^^^^^^^^^^^^^
  File "C:\Python311\Lib\site-packages\rest_framework\views.py", line 469, in handle_exception
    self.raise_uncaught_exception(exc)
  File "C:\Python311\Lib\site-packages\rest_framework\views.py", line 480, in raise_uncaught_exception
    raise exc
  File "C:\Python311\Lib\site-packages\rest_framework\views.py", line 506, in dispatch
    response = handler(request, *args, **kwargs)
               ^^^^^^^^^^^^^^^^^^^^^^^^^^^^^^^^^
  File "C:\Python311\Lib\site-packages\rest_framework\decorators.py", line 50, in handler
    return func(*args, **kwargs)
           ^^^^^^^^^^^^^^^^^^^^^
  File "C:\Users\kbo00\OneDrive\바탕 화면\소개딩\asd\backend\unplug\user\views.py", line 46, in login
    dto = LoginRequest(json.loads(request.body))
          ^^^^^^^^^^^^^^^^^^^^^^^^^^^^^^^^^^^^^^
  File "C:\Users\kbo00\OneDrive\바탕 화면\소개딩\asd\backend\unplug\user\views.py", line 32, in __init__
    self.username = body['username']
                    ~~~~^^^^^^^^^^^^
KeyError: 'username'
[2022-08-25 06:56:47] ERROR "POST /users/login HTTP/1.1" 500 145
[2022-08-25 06:56:47] ERROR Internal Server Error: /users/login
Traceback (most recent call last):
  File "C:\Python311\Lib\site-packages\django\core\handlers\exception.py", line 55, in inner
    response = get_response(request)
               ^^^^^^^^^^^^^^^^^^^^^
  File "C:\Python311\Lib\site-packages\django\core\handlers\base.py", line 197, in _get_response
    response = wrapped_callback(request, *callback_args, **callback_kwargs)
               ^^^^^^^^^^^^^^^^^^^^^^^^^^^^^^^^^^^^^^^^^^^^^^^^^^^^^^^^^^^^
  File "C:\Python311\Lib\site-packages\django\views\decorators\csrf.py", line 54, in wrapped_view
    return view_func(*args, **kwargs)
           ^^^^^^^^^^^^^^^^^^^^^^^^^^
  File "C:\Python311\Lib\site-packages\django\views\generic\base.py", line 103, in view
    return self.dispatch(request, *args, **kwargs)
           ^^^^^^^^^^^^^^^^^^^^^^^^^^^^^^^^^^^^^^^
  File "C:\Python311\Lib\site-packages\rest_framework\views.py", line 509, in dispatch
    response = self.handle_exception(exc)
               ^^^^^^^^^^^^^^^^^^^^^^^^^^
  File "C:\Python311\Lib\site-packages\rest_framework\views.py", line 469, in handle_exception
    self.raise_uncaught_exception(exc)
  File "C:\Python311\Lib\site-packages\rest_framework\views.py", line 480, in raise_uncaught_exception
    raise exc
  File "C:\Python311\Lib\site-packages\rest_framework\views.py", line 506, in dispatch
    response = handler(request, *args, **kwargs)
               ^^^^^^^^^^^^^^^^^^^^^^^^^^^^^^^^^
  File "C:\Python311\Lib\site-packages\rest_framework\decorators.py", line 50, in handler
    return func(*args, **kwargs)
           ^^^^^^^^^^^^^^^^^^^^^
  File "C:\Users\kbo00\OneDrive\바탕 화면\소개딩\asd\backend\unplug\user\views.py", line 46, in login
    dto = LoginRequest(json.loads(request.body))
          ^^^^^^^^^^^^^^^^^^^^^^^^^^^^^^^^^^^^^^
  File "C:\Users\kbo00\OneDrive\바탕 화면\소개딩\asd\backend\unplug\user\views.py", line 32, in __init__
    self.username = body['username']
                    ~~~~^^^^^^^^^^^^
KeyError: 'username'
[2022-08-25 06:56:47] ERROR "POST /users/login HTTP/1.1" 500 145
[2022-08-25 06:56:48] ERROR Internal Server Error: /users/login
Traceback (most recent call last):
  File "C:\Python311\Lib\site-packages\django\core\handlers\exception.py", line 55, in inner
    response = get_response(request)
               ^^^^^^^^^^^^^^^^^^^^^
  File "C:\Python311\Lib\site-packages\django\core\handlers\base.py", line 197, in _get_response
    response = wrapped_callback(request, *callback_args, **callback_kwargs)
               ^^^^^^^^^^^^^^^^^^^^^^^^^^^^^^^^^^^^^^^^^^^^^^^^^^^^^^^^^^^^
  File "C:\Python311\Lib\site-packages\django\views\decorators\csrf.py", line 54, in wrapped_view
    return view_func(*args, **kwargs)
           ^^^^^^^^^^^^^^^^^^^^^^^^^^
  File "C:\Python311\Lib\site-packages\django\views\generic\base.py", line 103, in view
    return self.dispatch(request, *args, **kwargs)
           ^^^^^^^^^^^^^^^^^^^^^^^^^^^^^^^^^^^^^^^
  File "C:\Python311\Lib\site-packages\rest_framework\views.py", line 509, in dispatch
    response = self.handle_exception(exc)
               ^^^^^^^^^^^^^^^^^^^^^^^^^^
  File "C:\Python311\Lib\site-packages\rest_framework\views.py", line 469, in handle_exception
    self.raise_uncaught_exception(exc)
  File "C:\Python311\Lib\site-packages\rest_framework\views.py", line 480, in raise_uncaught_exception
    raise exc
  File "C:\Python311\Lib\site-packages\rest_framework\views.py", line 506, in dispatch
    response = handler(request, *args, **kwargs)
               ^^^^^^^^^^^^^^^^^^^^^^^^^^^^^^^^^
  File "C:\Python311\Lib\site-packages\rest_framework\decorators.py", line 50, in handler
    return func(*args, **kwargs)
           ^^^^^^^^^^^^^^^^^^^^^
  File "C:\Users\kbo00\OneDrive\바탕 화면\소개딩\asd\backend\unplug\user\views.py", line 46, in login
    dto = LoginRequest(json.loads(request.body))
          ^^^^^^^^^^^^^^^^^^^^^^^^^^^^^^^^^^^^^^
  File "C:\Users\kbo00\OneDrive\바탕 화면\소개딩\asd\backend\unplug\user\views.py", line 32, in __init__
    self.username = body['username']
                    ~~~~^^^^^^^^^^^^
KeyError: 'username'
[2022-08-25 06:56:48] ERROR "POST /users/login HTTP/1.1" 500 145
